<?xml version="1.0" encoding="utf-8"?>
<!-- This URDF was automatically created by SolidWorks to URDF Exporter! Originally created by Stephen Brawner (brawner@gmail.com) 
     Commit Version: 1.6.0-4-g7f85cfe  Build Version: 1.6.7995.38578
     For more information, please see http://wiki.ros.org/sw_urdf_exporter -->
<robot
  name="nfh1">
  <link
    name="base_link">
    <inertial>
      <origin
        xyz="3.38271077815477E-17 -0.00152665456174176 0.00013600619686752"
        rpy="0 0 0" />
      <mass
        value="0.0010106350811003" />
      <inertia
        ixx="8.21935074102693E-08"
        ixy="1.09069372994596E-22"
        ixz="-9.53793667748096E-23"
        iyy="8.91169172879906E-08"
        iyz="3.75545527808583E-10"
        izz="3.24854532993333E-08" />
    </inertial>
    <visual>
      <origin
        xyz="0 0 0"
        rpy="0 0 0" />
      <geometry>
        <mesh
          filename="../../nfh1/meshes/base_link.STL" />
      </geometry>
      <material
        name="">
        <color
          rgba="0.792156862745098 0.819607843137255 0.933333333333333 1" />
      </material>
    </visual>
    <collision>
      <origin
        xyz="0 0 0"
        rpy="0 0 0" />
      <geometry>
        <mesh
          filename="../../nfh1/meshes/base_link.STL" />
      </geometry>
    </collision>
  </link>
  <link
    name="link1">
    <inertial>
      <origin
        xyz="-3.02968277956714E-08 0.00113442134572195 -0.00103189701894815"
        rpy="0 0 0" />
      <mass
        value="0.000198782228473331" />
      <inertia
        ixx="1.54756445032477E-09"
        ixy="1.04920853826156E-14"
        ixz="1.20628751644808E-14"
        iyy="7.78597837435174E-09"
        iyz="2.60644031070248E-11"
        izz="6.52448985383517E-09" />
    </inertial>
    <visual>
      <origin
        xyz="0 0 0"
        rpy="0 0 0" />
      <geometry>
        <mesh
          filename="../../nfh1/meshes/link1.STL" />
      </geometry>
      <material
        name="">
        <color
          rgba="0.792156862745098 0.819607843137255 0.933333333333333 1" />
      </material>
    </visual>
    <collision>
      <origin
        xyz="0 0 0"
        rpy="0 0 0" />
      <geometry>
        <mesh
          filename="../../nfh1/meshes/link1.STL" />
      </geometry>
    </collision>
  </link>
  <joint
    name="joint1"
    type="revolute">
    <origin
      xyz="0 0.002 -0.00043547"
      rpy="0 0 0" />
    <parent
      link="base_link" />
    <child
      link="link1" />
    <axis
      xyz="1 0 0" />
    <limit
      lower="0"
      upper="3"
      effort="0"
      velocity="0" />
  </joint>
  <link
    name="link2">
    <inertial>
      <origin
        xyz="2.04116237800811E-14 0.00199999999999673 2.25687524224583E-15"
        rpy="0 0 0" />
      <mass
        value="0.000426578933420392" />
      <inertia
        ixx="2.40312572201313E-08"
        ixy="1.08441426979082E-20"
        ixz="1.58390450486601E-14"
        iyy="5.02579655004393E-08"
        iyz="-8.12741302547014E-22"
        izz="2.69722292223729E-08" />
    </inertial>
    <visual>
      <origin
        xyz="0 0 0"
        rpy="0 0 0" />
      <geometry>
        <mesh
          filename="../../nfh1/meshes/link2.STL" />
      </geometry>
      <material
        name="">
        <color
          rgba="0.792156862745098 0.819607843137255 0.933333333333333 1" />
      </material>
    </visual>
    <collision>
      <origin
        xyz="0 0 0"
        rpy="0 0 0" />
      <geometry>
        <mesh
          filename="../../nfh1/meshes/link2.STL" />
      </geometry>
    </collision>
  </link>
  <joint
    name="joint2"
    type="revolute">
    <origin
      xyz="0 0.003 0"
      rpy="0 0 0" />
    <parent
      link="link1" />
    <child
      link="link2" />
    <axis
      xyz="1 0 0" />
    <limit
      lower="0"
      upper="3"
      effort="0"
      velocity="0" />
  </joint>
  <link
    name="link3">
    <inertial>
      <origin
        xyz="-1.85210429458349E-09 0.00188788673228118 9.25942005708391E-09"
        rpy="0 0 0" />
      <mass
        value="0.000177041699595263" />
      <inertia
        ixx="1.04521718092597E-09"
        ixy="8.84382829525734E-16"
        ixz="-3.68957976869567E-14"
        iyy="6.780090216707E-09"
        iyz="3.47697738614603E-16"
        izz="5.99075813384719E-09" />
    </inertial>
    <visual>
      <origin
        xyz="0 0 0"
        rpy="0 0 0" />
      <geometry>
        <mesh
          filename="../../nfh1/meshes/link3.STL" />
      </geometry>
      <material
        name="">
        <color
          rgba="0.792156862745098 0.819607843137255 0.933333333333333 1" />
      </material>
    </visual>
    <collision>
      <origin
        xyz="0 0 0"
        rpy="0 0 0" />
      <geometry>
        <mesh
          filename="../../nfh1/meshes/link3.STL" />
      </geometry>
    </collision>
  </link>
  <joint
    name="joint3"
    type="revolute">
    <origin
      xyz="0 0.004 0"
      rpy="0 0 0" />
    <parent
      link="link2" />
    <child
      link="link3" />
    <axis
      xyz="1 0 0" />
    <limit
      lower="0"
      upper="3"
      effort="0"
      velocity="0" />
  </joint>
  <link
    name="link4">
    <inertial>
      <origin
        xyz="-1.85220484522769E-09 0.00111211326769552 -9.25926902685392E-09"
        rpy="0 0 0" />
      <mass
        value="0.000177041699591455" />
      <inertia
        ixx="1.04521718092059E-09"
        ixy="-8.84414594885132E-16"
        ixz="3.68958562620462E-14"
        iyy="6.78009021647453E-09"
        iyz="3.47696486133909E-16"
        izz="5.99075813360752E-09" />
    </inertial>
    <visual>
      <origin
        xyz="0 0 0"
        rpy="0 0 0" />
      <geometry>
        <mesh
          filename="../../nfh1/meshes/link4.STL" />
      </geometry>
      <material
        name="">
        <color
          rgba="0.792156862745098 0.819607843137255 0.933333333333333 1" />
      </material>
    </visual>
    <collision>
      <origin
        xyz="0 0 0"
        rpy="0 0 0" />
      <geometry>
        <mesh
          filename="../../nfh1/meshes/link4.STL" />
      </geometry>
    </collision>
  </link>
  <joint
    name="joint4"
    type="revolute">
    <origin
      xyz="0 0.003 0"
      rpy="0 0 0" />
    <parent
      link="link3" />
    <child
      link="link4" />
    <axis
      xyz="1 0 0" />
    <limit
      lower="0"
      upper="3"
      effort="0"
      velocity="0" />
  </joint>
  <link
    name="link5">
    <inertial>
      <origin
        xyz="3.16587034365767E-16 0.00199999999999984 2.94902990916057E-17"
        rpy="0 0 0" />
      <mass
        value="0.000426578933419002" />
      <inertia
        ixx="2.40312572201162E-08"
        ixy="5.53023048996122E-22"
        ixz="1.58390444679449E-14"
        iyy="5.02579655003556E-08"
        iyz="3.33937442954536E-22"
        izz="2.69722292223007E-08" />
    </inertial>
    <visual>
      <origin
        xyz="0 0 0"
        rpy="0 0 0" />
      <geometry>
        <mesh
          filename="../../nfh1/meshes/link5.STL" />
      </geometry>
      <material
        name="">
        <color
          rgba="0.792156862745098 0.819607843137255 0.933333333333333 1" />
      </material>
    </visual>
    <collision>
      <origin
        xyz="0 0 0"
        rpy="0 0 0" />
      <geometry>
        <mesh
          filename="../../nfh1/meshes/link5.STL" />
      </geometry>
    </collision>
  </link>
  <joint
    name="joint5"
    type="revolute">
    <origin
      xyz="0 0.003 0"
      rpy="0 0 0" />
    <parent
      link="link4" />
    <child
      link="link5" />
    <axis
      xyz="1 0 0" />
    <limit
      lower="0"
      upper="3"
      effort="0"
      velocity="0" />
  </joint>
  <link
    name="link6">
    <inertial>
      <origin
        xyz="-1.85304629713584E-09 0.00188788673222637 9.25894851587505E-09"
        rpy="0 0 0" />
      <mass
        value="0.000177041699612827" />
      <inertia
        ixx="1.04521718094737E-09"
        ixy="8.84331514880089E-16"
        ixz="-3.68957016060218E-14"
        iyy="6.78009021785023E-09"
        iyz="3.47704440244518E-16"
        izz="5.99075813499962E-09" />
    </inertial>
    <visual>
      <origin
        xyz="0 0 0"
        rpy="0 0 0" />
      <geometry>
        <mesh
          filename="../../nfh1/meshes/link6.STL" />
      </geometry>
      <material
        name="">
        <color
          rgba="0.792156862745098 0.819607843137255 0.933333333333333 1" />
      </material>
    </visual>
    <collision>
      <origin
        xyz="0 0 0"
        rpy="0 0 0" />
      <geometry>
        <mesh
          filename="../../nfh1/meshes/link6.STL" />
      </geometry>
    </collision>
  </link>
  <joint
    name="joint6"
    type="revolute">
    <origin
      xyz="0 0.004 0"
      rpy="0 0 0" />
    <parent
      link="link5" />
    <child
      link="link6" />
    <axis
      xyz="1 0 0" />
    <limit
      lower="0"
      upper="3"
      effort="0"
      velocity="0" />
  </joint>
  <link
    name="link7">
    <inertial>
      <origin
        xyz="-1.85217126965481E-09 0.00111211326771995 -9.2592722395618E-09"
        rpy="0 0 0" />
      <mass
        value="0.000177041699592343" />
      <inertia
        ixx="1.04521718091653E-09"
        ixy="-8.84384732571617E-16"
        ixz="3.68959110097901E-14"
        iyy="6.78009021664487E-09"
        iyz="3.47696110296643E-16"
        izz="5.99075813379512E-09" />
    </inertial>
    <visual>
      <origin
        xyz="0 0 0"
        rpy="0 0 0" />
      <geometry>
        <mesh
          filename="../../nfh1/meshes/link7.STL" />
      </geometry>
      <material
        name="">
        <color
          rgba="0.792156862745098 0.819607843137255 0.933333333333333 1" />
      </material>
    </visual>
    <collision>
      <origin
        xyz="0 0 0"
        rpy="0 0 0" />
      <geometry>
        <mesh
          filename="../../nfh1/meshes/link7.STL" />
      </geometry>
    </collision>
  </link>
  <joint
    name="joint7"
    type="revolute">
    <origin
      xyz="0 0.003 0"
      rpy="0 0 0" />
    <parent
      link="link6" />
    <child
      link="link7" />
    <axis
      xyz="1 0 0" />
    <limit
      lower="0"
      upper="3"
      effort="0"
      velocity="0" />
  </joint>
  <link
    name="link8">
    <inertial>
      <origin
        xyz="-3.03888357620213E-09 0.00259277247993408 -0.00095049373758898"
        rpy="0 0 0" />
      <mass
        value="0.0010266417760455" />
      <inertia
        ixx="4.11004796506741E-08"
        ixy="-2.66382276095118E-14"
        ixz="-1.7805024963789E-14"
        iyy="8.86548394837283E-08"
        iyz="5.31597018204856E-10"
        izz="4.92201079166408E-08" />
    </inertial>
    <visual>
      <origin
        xyz="0 0 0"
        rpy="0 0 0" />
      <geometry>
        <mesh
          filename="../../nfh1/meshes/link8.STL" />
      </geometry>
      <material
        name="">
        <color
          rgba="0.792156862745098 0.819607843137255 0.933333333333333 1" />
      </material>
    </visual>
    <collision>
      <origin
        xyz="0 0 0"
        rpy="0 0 0" />
      <geometry>
        <mesh
          filename="../../nfh1/meshes/link8.STL" />
      </geometry>
    </collision>
  </link>
  <joint
    name="joint8"
    type="revolute">
    <origin
      xyz="0 0.003 0"
      rpy="0 0 0" />
    <parent
      link="link7" />
    <child
      link="link8" />
    <axis
      xyz="1 0 0" />
    <limit
      lower="0"
      upper="3"
      effort="0"
      velocity="0" />
  </joint>
  <link
    name="link9">
    <inertial>
      <origin
        xyz="-5.46437894932694E-17 0.000833333333333332 -1.73472347597681E-18"
        rpy="0 0 0" />
      <mass
        value="8.10000000000002E-05" />
      <inertia
        ixx="8.43750000000006E-11"
        ixy="2.92242883488534E-24"
        ixz="-8.55086023776014E-25"
        iyy="2.31075000000001E-09"
        iyz="-2.97461309303528E-26"
        izz="2.27362500000001E-09" />
    </inertial>
    <visual>
      <origin
        xyz="0 0 0"
        rpy="0 0 0" />
      <geometry>
        <mesh
          filename="../../nfh1/meshes/link9.STL" />
      </geometry>
      <material
        name="">
        <color
          rgba="0.792156862745098 0.819607843137255 0.933333333333333 1" />
      </material>
    </visual>
    <collision>
      <origin
        xyz="0 0 0"
        rpy="0 0 0" />
      <geometry>
        <mesh
          filename="../../nfh1/meshes/link9.STL" />
      </geometry>
    </collision>
  </link>
  <joint
    name="joint9"
    type="revolute">
    <origin
      xyz="0 0.004 0"
      rpy="0 0 0" />
    <parent
      link="link8" />
    <child
      link="link9" />
    <axis
      xyz="1 0 0" />
    <limit
      lower="0"
      upper="3"
      effort="0"
      velocity="0" />
  </joint>
  <link
    name="link10">
    <inertial>
      <origin
        xyz="-5.63785129692462E-17 0.00116666666666666 -1.73472347597681E-18"
        rpy="0 0 0" />
      <mass
        value="8.10000000000005E-05" />
      <inertia
        ixx="8.43750000000004E-11"
        ixy="-3.07542157065845E-24"
        ixz="3.42796988361759E-25"
        iyy="2.31075000000001E-09"
        iyz="1.86720834430788E-26"
        izz="2.27362500000001E-09" />
    </inertial>
    <visual>
      <origin
        xyz="0 0 0"
        rpy="0 0 0" />
      <geometry>
        <mesh
          filename="../../nfh1/meshes/link10.STL" />
      </geometry>
      <material
        name="">
        <color
          rgba="0.792156862745098 0.819607843137255 0.933333333333333 1" />
      </material>
    </visual>
    <collision>
      <origin
        xyz="0 0 0"
        rpy="0 0 0" />
      <geometry>
        <mesh
          filename="../../nfh1/meshes/link10.STL" />
      </geometry>
    </collision>
  </link>
  <joint
    name="joint10"
    type="revolute">
    <origin
      xyz="0 0.002 0"
      rpy="0 0 0" />
    <parent
      link="link9" />
    <child
      link="link10" />
    <axis
      xyz="1 0 0" />
    <limit
      lower="0"
      upper="3"
      effort="0"
      velocity="0" />
  </joint>
  <link
    name="link11">
    <inertial>
      <origin
        xyz="-3.64291929955129E-17 0.000833333333333332 -1.73472347597681E-18"
        rpy="0 0 0" />
      <mass
        value="8.09999999999997E-05" />
      <inertia
        ixx="8.43749999999972E-11"
        ixy="1.96738543955592E-24"
        ixz="-3.05994319520648E-25"
        iyy="2.31075E-09"
        iyz="-2.13678943482114E-26"
        izz="2.273625E-09" />
    </inertial>
    <visual>
      <origin
        xyz="0 0 0"
        rpy="0 0 0" />
      <geometry>
        <mesh
          filename="../../nfh1/meshes/link11.STL" />
      </geometry>
      <material
        name="">
        <color
          rgba="0.792156862745098 0.819607843137255 0.933333333333333 1" />
      </material>
    </visual>
    <collision>
      <origin
        xyz="0 0 0"
        rpy="0 0 0" />
      <geometry>
        <mesh
          filename="../../nfh1/meshes/link11.STL" />
      </geometry>
    </collision>
  </link>
  <joint
    name="joint11"
    type="revolute">
    <origin
      xyz="0 0.002 0"
      rpy="0 0 0" />
    <parent
      link="link10" />
    <child
      link="link11" />
    <axis
      xyz="1 0 0" />
    <limit
      lower="0"
      upper="3"
      effort="0"
      velocity="0" />
  </joint>
  <link
    name="link12">
    <inertial>
      <origin
        xyz="-3.72965547335014E-17 0.00116666666666667 -1.73472347597681E-18"
        rpy="0 0 0" />
      <mass
        value="8.10000000000007E-05" />
      <inertia
        ixx="8.43750000000011E-11"
        ixy="-1.93605819528781E-24"
        ixz="-2.95930406553499E-26"
        iyy="2.31075000000001E-09"
        iyz="9.95985777925864E-27"
        izz="2.27362500000001E-09" />
    </inertial>
    <visual>
      <origin
        xyz="0 0 0"
        rpy="0 0 0" />
      <geometry>
        <mesh
          filename="../../nfh1/meshes/link12.STL" />
      </geometry>
      <material
        name="">
        <color
          rgba="0.792156862745098 0.819607843137255 0.933333333333333 1" />
      </material>
    </visual>
    <collision>
      <origin
        xyz="0 0 0"
        rpy="0 0 0" />
      <geometry>
        <mesh
          filename="../../nfh1/meshes/link12.STL" />
      </geometry>
    </collision>
  </link>
  <joint
    name="joint12"
    type="revolute">
    <origin
      xyz="0 0.002 0"
      rpy="0 0 0" />
    <parent
      link="link11" />
    <child
      link="link12" />
    <axis
      xyz="1 0 0" />
    <limit
      lower="0"
      upper="3"
      effort="0"
      velocity="0" />
  </joint>
  <link
    name="link13">
    <inertial>
      <origin
        xyz="-1.90819582357449E-17 0.000833333333333339 1.73472347597681E-18"
        rpy="0 0 0" />
      <mass
        value="8.09999999999995E-05" />
      <inertia
        ixx="8.43749999999985E-11"
        ixy="1.0021015778622E-24"
        ixz="-2.80106875926232E-25"
        iyy="2.31075E-09"
        iyz="-3.81924985088125E-26"
        izz="2.273625E-09" />
    </inertial>
    <visual>
      <origin
        xyz="0 0 0"
        rpy="0 0 0" />
      <geometry>
        <mesh
          filename="../../nfh1/meshes/link13.STL" />
      </geometry>
      <material
        name="">
        <color
          rgba="0.792156862745098 0.819607843137255 0.933333333333333 1" />
      </material>
    </visual>
    <collision>
      <origin
        xyz="0 0 0"
        rpy="0 0 0" />
      <geometry>
        <mesh
          filename="../../nfh1/meshes/link13.STL" />
      </geometry>
    </collision>
  </link>
  <joint
    name="joint13"
    type="revolute">
    <origin
      xyz="0 0.002 0"
      rpy="0 0 0" />
    <parent
      link="link12" />
    <child
      link="link13" />
    <axis
      xyz="1 0 0" />
    <limit
      lower="0"
      upper="3"
      effort="0"
      velocity="0" />
  </joint>
  <link
    name="link14">
    <inertial>
      <origin
        xyz="-1.82145964977565E-17 0.00116666666666666 0"
        rpy="0 0 0" />
      <mass
        value="8.10000000000009E-05" />
      <inertia
        ixx="8.43750000000015E-11"
        ixy="-1.01141644743106E-24"
        ixz="2.30587450828703E-25"
        iyy="2.31075000000001E-09"
        iyz="-7.05249727203203E-27"
        izz="2.27362500000001E-09" />
    </inertial>
    <visual>
      <origin
        xyz="0 0 0"
        rpy="0 0 0" />
      <geometry>
        <mesh
          filename="../../nfh1/meshes/link14.STL" />
      </geometry>
      <material
        name="">
        <color
          rgba="0.792156862745098 0.819607843137255 0.933333333333333 1" />
      </material>
    </visual>
    <collision>
      <origin
        xyz="0 0 0"
        rpy="0 0 0" />
      <geometry>
        <mesh
          filename="../../nfh1/meshes/link14.STL" />
      </geometry>
    </collision>
  </link>
  <joint
    name="joint14"
    type="revolute">
    <origin
      xyz="0 0.002 0"
      rpy="0 0 0" />
    <parent
      link="link13" />
    <child
      link="link14" />
    <axis
      xyz="1 0 0" />
    <limit
      lower="0"
      upper="3"
      effort="0"
      velocity="0" />
  </joint>
  <link
    name="link15">
    <inertial>
      <origin
        xyz="0 0.00083333 1.7347E-18"
        rpy="0 0 0" />
      <mass
        value="8.1E-05" />
      <inertia
        ixx="8.4375E-11"
        ixy="9.7337E-26"
        ixz="3.4405E-25"
        iyy="2.3107E-09"
        iyz="-1.032E-25"
        izz="2.2736E-09" />
    </inertial>
    <visual>
      <origin
        xyz="0 0 0"
        rpy="0 0 0" />
      <geometry>
        <mesh
          filename="../../nfh1/meshes/link15.STL" />
      </geometry>
      <material
        name="">
        <color
          rgba="0.79216 0.81961 0.93333 1" />
      </material>
    </visual>
    <collision>
      <origin
        xyz="0 0 0"
        rpy="0 0 0" />
      <geometry>
        <mesh
          filename="../../nfh1/meshes/link15.STL" />
      </geometry>
    </collision>
  </link>
  <joint
    name="joint15"
    type="revolute">
    <origin
      xyz="0 0.002 0"
      rpy="0 0 0" />
    <parent
      link="link14" />
    <child
      link="link15" />
    <axis
      xyz="1 0 0" />
    <limit
      lower="0"
      upper="3"
      effort="0"
      velocity="0" />
  </joint>
  <link
    name="link16">
    <inertial>
      <origin
        xyz="-8.67361737988404E-19 0.00116666666666665 -1.73472347597681E-18"
        rpy="0 0 0" />
      <mass
        value="8.09999999999998E-05" />
      <inertia
        ixx="8.43750000000003E-11"
        ixy="-1.45597427740292E-25"
        ixz="1.33569597137202E-25"
        iyy="2.31074999999998E-09"
        iyz="-5.16546120738732E-27"
        izz="2.27362499999998E-09" />
    </inertial>
    <visual>
      <origin
        xyz="0 0 0"
        rpy="0 0 0" />
      <geometry>
        <mesh
          filename="../../nfh1/meshes/link16.STL" />
      </geometry>
      <material
        name="">
        <color
          rgba="0.792156862745098 0.819607843137255 0.933333333333333 1" />
      </material>
    </visual>
    <collision>
      <origin
        xyz="0 0 0"
        rpy="0 0 0" />
      <geometry>
        <mesh
          filename="../../nfh1/meshes/link16.STL" />
      </geometry>
    </collision>
  </link>
  <joint
    name="joint16"
    type="revolute">
    <origin
      xyz="0 0.002 0"
      rpy="0 0 0" />
    <parent
      link="link15" />
    <child
      link="link16" />
    <axis
      xyz="1 0 0" />
    <limit
      lower="0"
      upper="3"
      effort="0"
      velocity="0" />
  </joint>
  <link
    name="link17">
    <inertial>
      <origin
        xyz="3.0389E-09 0.0014072 -0.00095049"
        rpy="0 0 0" />
      <mass
        value="0.0010266" />
      <inertia
        ixx="4.11E-08"
        ixy="-2.6638E-14"
        ixz="1.7805E-14"
        iyy="8.8655E-08"
        iyz="-5.316E-10"
        izz="4.922E-08" />
    </inertial>
    <visual>
      <origin
        xyz="0 0 0"
        rpy="0 0 0" />
      <geometry>
        <mesh
          filename="../../nfh1/meshes/link17.STL" />
      </geometry>
      <material
        name="">
        <color
          rgba="0.79216 0.81961 0.93333 1" />
      </material>
    </visual>
    <collision>
      <origin
        xyz="0 0 0"
        rpy="0 0 0" />
      <geometry>
        <mesh
          filename="../../nfh1/meshes/link17.STL" />
      </geometry>
    </collision>
  </link>
  <joint
    name="joint17"
    type="revolute">
    <origin
      xyz="0 0.002 0"
      rpy="0 0 0" />
    <parent
      link="link16" />
    <child
      link="link17" />
    <axis
      xyz="1 0 0" />
    <limit
      lower="0"
      upper="3"
      effort="0"
      velocity="0" />
  </joint>
  <link
    name="link18">
    <inertial>
      <origin
        xyz="-1.85210907721611E-09 0.00188788673228193 9.25941985932544E-09"
        rpy="0 0 0" />
      <mass
        value="0.000177041699595134" />
      <inertia
        ixx="1.04521718092574E-09"
        ixy="8.84381809648875E-16"
        ixz="-3.68957976733367E-14"
        iyy="6.78009021670153E-09"
        iyz="3.47697753969144E-16"
        izz="5.99075813384154E-09" />
    </inertial>
    <visual>
      <origin
        xyz="0 0 0"
        rpy="0 0 0" />
      <geometry>
        <mesh
          filename="../../nfh1/meshes/link18.STL" />
      </geometry>
      <material
        name="">
        <color
          rgba="0.792156862745098 0.819607843137255 0.933333333333333 1" />
      </material>
    </visual>
    <collision>
      <origin
        xyz="0 0 0"
        rpy="0 0 0" />
      <geometry>
        <mesh
          filename="../../nfh1/meshes/link18.STL" />
      </geometry>
    </collision>
  </link>
  <joint
    name="joint18"
    type="revolute">
    <origin
      xyz="0 0.004 0"
      rpy="0 0 0" />
    <parent
      link="link17" />
    <child
      link="link18" />
    <axis
      xyz="1 0 0" />
    <limit
      lower="0"
      upper="3"
      effort="0"
      velocity="0" />
  </joint>
  <link
    name="link19">
    <inertial>
      <origin
        xyz="-1.85312260588683E-09 0.00111211326777413 -9.2596469467715E-09"
        rpy="0 0 0" />
      <mass
        value="0.00017704169961621" />
      <inertia
        ixx="1.045217180958E-09"
        ixy="-8.84332056180977E-16"
        ixz="3.68960054813993E-14"
        iyy="6.78009021793177E-09"
        iyz="3.47689119657577E-16"
        izz="5.99075813507066E-09" />
    </inertial>
    <visual>
      <origin
        xyz="0 0 0"
        rpy="0 0 0" />
      <geometry>
        <mesh
          filename="../../nfh1/meshes/link19.STL" />
      </geometry>
      <material
        name="">
        <color
          rgba="0.792156862745098 0.819607843137255 0.933333333333333 1" />
      </material>
    </visual>
    <collision>
      <origin
        xyz="0 0 0"
        rpy="0 0 0" />
      <geometry>
        <mesh
          filename="../../nfh1/meshes/link19.STL" />
      </geometry>
    </collision>
  </link>
  <joint
    name="joint19"
    type="revolute">
    <origin
      xyz="0 0.003 0"
      rpy="0 0 0" />
    <parent
      link="link18" />
    <child
      link="link19" />
    <axis
      xyz="1 0 0" />
    <limit
      lower="0"
      upper="3"
      effort="0"
      velocity="0" />
  </joint>
  <link
    name="link20">
    <inertial>
      <origin
        xyz="2.949E-16 0.002 -6.245E-17"
        rpy="0 0 0" />
      <mass
        value="0.00042658" />
      <inertia
        ixx="2.4031E-08"
        ixy="-5.7522E-22"
        ixz="-1.5839E-14"
        iyy="5.0258E-08"
        iyz="-3.241E-22"
        izz="2.6972E-08" />
    </inertial>
    <visual>
      <origin
        xyz="0 0 0"
        rpy="0 0 0" />
      <geometry>
        <mesh
          filename="../../nfh1/meshes/link20.STL" />
      </geometry>
      <material
        name="">
        <color
          rgba="0.79216 0.81961 0.93333 1" />
      </material>
    </visual>
    <collision>
      <origin
        xyz="0 0 0"
        rpy="0 0 0" />
      <geometry>
        <mesh
          filename="../../nfh1/meshes/link20.STL" />
      </geometry>
    </collision>
  </link>
  <joint
    name="joint20"
    type="revolute">
    <origin
      xyz="0 0.003 0"
      rpy="0 0 0" />
    <parent
      link="link19" />
    <child
      link="link20" />
    <axis
      xyz="1 0 0" />
    <limit
      lower="0"
      upper="3"
      effort="0"
      velocity="0" />
  </joint>
  <link
    name="link21">
    <inertial>
      <origin
        xyz="-1.85212578520527E-09 0.00188788673230469 9.2593287238929E-09"
        rpy="0 0 0" />
      <mass
        value="0.000177041699588148" />
      <inertia
        ixx="1.04521718091002E-09"
        ixy="8.84414436874819E-16"
        ixz="-3.68958511803103E-14"
        iyy="6.78009021639738E-09"
        iyz="3.47697111230421E-16"
        izz="5.99075813354088E-09" />
    </inertial>
    <visual>
      <origin
        xyz="0 0 0"
        rpy="0 0 0" />
      <geometry>
        <mesh
          filename="../../nfh1/meshes/link21.STL" />
      </geometry>
      <material
        name="">
        <color
          rgba="0.792156862745098 0.819607843137255 0.933333333333333 1" />
      </material>
    </visual>
    <collision>
      <origin
        xyz="0 0 0"
        rpy="0 0 0" />
      <geometry>
        <mesh
          filename="../../nfh1/meshes/link21.STL" />
      </geometry>
    </collision>
  </link>
  <joint
    name="joint21"
    type="revolute">
    <origin
      xyz="0 0.004 0"
      rpy="0 0 0" />
    <parent
      link="link20" />
    <child
      link="link21" />
    <axis
      xyz="1 0 0" />
    <limit
      lower="0"
      upper="3"
      effort="0"
      velocity="0" />
  </joint>
  <link
    name="link22">
    <inertial>
      <origin
        xyz="-1.8522E-09 0.0011121 -9.2593E-09"
        rpy="0 0 0" />
      <mass
        value="0.00017704" />
      <inertia
        ixx="1.0452E-09"
        ixy="-8.8438E-16"
        ixz="3.6896E-14"
        iyy="6.7801E-09"
        iyz="3.477E-16"
        izz="5.9908E-09" />
    </inertial>
    <visual>
      <origin
        xyz="0 0 0"
        rpy="0 0 0" />
      <geometry>
        <mesh
          filename="../../nfh1/meshes/link22.STL" />
      </geometry>
      <material
        name="">
        <color
          rgba="0.79216 0.81961 0.93333 1" />
      </material>
    </visual>
    <collision>
      <origin
        xyz="0 0 0"
        rpy="0 0 0" />
      <geometry>
        <mesh
          filename="../../nfh1/meshes/link22.STL" />
      </geometry>
    </collision>
  </link>
  <joint
    name="joint22"
    type="revolute">
    <origin
      xyz="0 0.003 0"
      rpy="0 0 0" />
    <parent
      link="link21" />
    <child
      link="link22" />
    <axis
      xyz="1 0 0" />
    <limit
      lower="0"
      upper="3"
      effort="0"
      velocity="0" />
  </joint>
  <link
    name="link23">
    <inertial>
      <origin
        xyz="-4.25528023494798E-09 0.00200319378405478 1.99201304004071E-05"
        rpy="0 0 0" />
      <mass
        value="0.000427551960688234" />
      <inertia
        ixx="2.41076400365124E-08"
        ixy="7.90954943747629E-15"
        ixz="-3.44632846965697E-15"
        iyy="5.03556158003561E-08"
        iyz="-1.18913452372501E-11"
        izz="2.69974746683614E-08" />
    </inertial>
    <visual>
      <origin
        xyz="0 0 0"
        rpy="0 0 0" />
      <geometry>
        <mesh
          filename="../../nfh1/meshes/link23.STL" />
      </geometry>
      <material
        name="">
        <color
          rgba="0.792156862745098 0.819607843137255 0.933333333333333 1" />
      </material>
    </visual>
    <collision>
      <origin
        xyz="0 0 0"
        rpy="0 0 0" />
      <geometry>
        <mesh
          filename="../../nfh1/meshes/link23.STL" />
      </geometry>
    </collision>
  </link>
  <joint
    name="joint23"
    type="revolute">
    <origin
      xyz="0 0.003 0"
      rpy="0 0 0" />
    <parent
      link="link22" />
    <child
      link="link23" />
    <axis
      xyz="1 0 0" />
    <limit
      lower="0"
      upper="3"
      effort="0"
      velocity="0" />
  </joint>
  <link
    name="link24">
    <inertial>
      <origin
        xyz="-3.38201900512702E-10 0.00188674420392113 5.18032967219001E-05"
        rpy="0 0 0" />
      <mass
        value="0.000178474248585628" />
      <inertia
        ixx="1.05271305605121E-09"
        ixy="7.39128121421579E-16"
        ixz="-3.65658382248024E-14"
        iyy="6.82195048329844E-09"
        iyz="5.92149616895043E-13"
        izz="6.02540767877401E-09" />
    </inertial>
    <visual>
      <origin
        xyz="0 0 0"
        rpy="0 0 0" />
      <geometry>
        <mesh
          filename="../../nfh1/meshes/link24.STL" />
      </geometry>
      <material
        name="">
        <color
          rgba="0.792156862745098 0.819607843137255 0.933333333333333 1" />
      </material>
    </visual>
    <collision>
      <origin
        xyz="0 0 0"
        rpy="0 0 0" />
      <geometry>
        <mesh
          filename="../../nfh1/meshes/link24.STL" />
      </geometry>
    </collision>
  </link>
  <joint
    name="joint24"
    type="revolute">
    <origin
      xyz="0 0.004 0"
      rpy="0 0 0" />
    <parent
      link="link23" />
    <child
      link="link24" />
    <axis
      xyz="1 0 0" />
    <limit
      lower="0"
      upper="3"
      effort="0"
      velocity="0" />
  </joint>
  <link
    name="link25">
    <inertial>
      <origin
        xyz="-1.17279588587524E-07 0.00934193942987209 -0.0010729332636391"
        rpy="0 0 0" />
      <mass
        value="0.00599011517829515" />
      <inertia
        ixx="3.31538192061756E-07"
        ixy="-1.75604651735912E-11"
        ixz="2.44055516157567E-12"
        iyy="2.98578307333115E-07"
        iyz="3.11639717813993E-08"
        izz="3.70079600322106E-07" />
    </inertial>
    <visual>
      <origin
        xyz="0 0 0"
        rpy="0 0 0" />
      <geometry>
        <mesh
          filename="../../nfh1/meshes/link25.STL" />
      </geometry>
      <material
        name="">
        <color
          rgba="0.792156862745098 0.819607843137255 0.933333333333333 1" />
      </material>
    </visual>
    <collision>
      <origin
        xyz="0 0 0"
        rpy="0 0 0" />
      <geometry>
        <mesh
          filename="../../nfh1/meshes/link25.STL" />
      </geometry>
    </collision>
  </link>
  <joint
    name="joint25"
    type="revolute">
    <origin
      xyz="0 0.003 0"
      rpy="0 0 0" />
    <parent
      link="link24" />
    <child
      link="link25" />
    <axis
      xyz="1 0 0" />
    <limit
      lower="0"
      upper="3"
      effort="0"
      velocity="0" />
  </joint>
</robot>